Loading nvidia/nvhpc/22.11
  Loading requirement: gcc/8.2.0
r2i6n[0-3]
Head node IP: 10.148.203.101
master_addr is only used for static rdzv_backend and when rdzv_endpoint is not specified.
master_addr is only used for static rdzv_backend and when rdzv_endpoint is not specified.
master_addr is only used for static rdzv_backend and when rdzv_endpoint is not specified.
master_addr is only used for static rdzv_backend and when rdzv_endpoint is not specified.
Traceback (most recent call last):
  File "/mnt/lustre/indy2lfs/work/sc118/sc118/xliao11/msc_project/train.py", line 1, in <module>
    from LatentPixel.training.pretrain_latent import train, get_config, init_wandb
  File "/mnt/lustre/indy2lfs/work/sc118/sc118/xliao11/msc_project/LatentPixel/__init__.py", line 1, in <module>
    from .modeling import (
  File "/mnt/lustre/indy2lfs/work/sc118/sc118/xliao11/msc_project/LatentPixel/modeling/__init__.py", line 1, in <module>
    from .pixels import LPixelForMLM, LPixelForClassification
  File "/mnt/lustre/indy2lfs/work/sc118/sc118/xliao11/msc_project/LatentPixel/modeling/pixels.py", line 9, in <module>
    from pixel import PIXELForPreTraining, PIXELEmbeddings
ImportError: cannot import name 'PIXELForPreTraining' from 'pixel' (unknown location)
Traceback (most recent call last):
  File "/mnt/lustre/indy2lfs/work/sc118/sc118/xliao11/msc_project/train.py", line 1, in <module>
    from LatentPixel.training.pretrain_latent import train, get_config, init_wandb
  File "/mnt/lustre/indy2lfs/work/sc118/sc118/xliao11/msc_project/LatentPixel/__init__.py", line 1, in <module>
    from .modeling import (
  File "/mnt/lustre/indy2lfs/work/sc118/sc118/xliao11/msc_project/LatentPixel/modeling/__init__.py", line 1, in <module>
    from .pixels import LPixelForMLM, LPixelForClassification
  File "/mnt/lustre/indy2lfs/work/sc118/sc118/xliao11/msc_project/LatentPixel/modeling/pixels.py", line 9, in <module>
    from pixel import PIXELForPreTraining, PIXELEmbeddings
ImportError: cannot import name 'PIXELForPreTraining' from 'pixel' (unknown location)
Traceback (most recent call last):
  File "/mnt/lustre/indy2lfs/work/sc118/sc118/xliao11/msc_project/train.py", line 1, in <module>
    from LatentPixel.training.pretrain_latent import train, get_config, init_wandb
  File "/mnt/lustre/indy2lfs/work/sc118/sc118/xliao11/msc_project/LatentPixel/__init__.py", line 1, in <module>
    from .modeling import (
  File "/mnt/lustre/indy2lfs/work/sc118/sc118/xliao11/msc_project/LatentPixel/modeling/__init__.py", line 1, in <module>
    from .pixels import LPixelForMLM, LPixelForClassification
  File "/mnt/lustre/indy2lfs/work/sc118/sc118/xliao11/msc_project/LatentPixel/modeling/pixels.py", line 9, in <module>
    from pixel import PIXELForPreTraining, PIXELEmbeddings
ImportError: cannot import name 'PIXELForPreTraining' from 'pixel' (unknown location)
Traceback (most recent call last):
Traceback (most recent call last):
  File "/mnt/lustre/indy2lfs/work/sc118/sc118/xliao11/msc_project/train.py", line 1, in <module>
  File "/mnt/lustre/indy2lfs/work/sc118/sc118/xliao11/msc_project/train.py", line 1, in <module>
Traceback (most recent call last):
  File "/mnt/lustre/indy2lfs/work/sc118/sc118/xliao11/msc_project/train.py", line 1, in <module>
        from LatentPixel.training.pretrain_latent import train, get_config, init_wandbfrom LatentPixel.training.pretrain_latent import train, get_config, init_wandb

  File "/mnt/lustre/indy2lfs/work/sc118/sc118/xliao11/msc_project/LatentPixel/__init__.py", line 1, in <module>
  File "/mnt/lustre/indy2lfs/work/sc118/sc118/xliao11/msc_project/LatentPixel/__init__.py", line 1, in <module>
    from LatentPixel.training.pretrain_latent import train, get_config, init_wandb
  File "/mnt/lustre/indy2lfs/work/sc118/sc118/xliao11/msc_project/LatentPixel/__init__.py", line 1, in <module>
    from .modeling import (
  File "/mnt/lustre/indy2lfs/work/sc118/sc118/xliao11/msc_project/LatentPixel/modeling/__init__.py", line 1, in <module>
    from .modeling import (
  File "/mnt/lustre/indy2lfs/work/sc118/sc118/xliao11/msc_project/LatentPixel/modeling/__init__.py", line 1, in <module>
    from .modeling import (
  File "/mnt/lustre/indy2lfs/work/sc118/sc118/xliao11/msc_project/LatentPixel/modeling/__init__.py", line 1, in <module>
    from .pixels import LPixelForMLM, LPixelForClassification
  File "/mnt/lustre/indy2lfs/work/sc118/sc118/xliao11/msc_project/LatentPixel/modeling/pixels.py", line 9, in <module>
    from .pixels import LPixelForMLM, LPixelForClassification
  File "/mnt/lustre/indy2lfs/work/sc118/sc118/xliao11/msc_project/LatentPixel/modeling/pixels.py", line 9, in <module>
    from .pixels import LPixelForMLM, LPixelForClassification
  File "/mnt/lustre/indy2lfs/work/sc118/sc118/xliao11/msc_project/LatentPixel/modeling/pixels.py", line 9, in <module>
Traceback (most recent call last):
  File "/mnt/lustre/indy2lfs/work/sc118/sc118/xliao11/msc_project/train.py", line 1, in <module>
        from pixel import PIXELForPreTraining, PIXELEmbeddingsfrom pixel import PIXELForPreTraining, PIXELEmbeddings

ImportErrorImportError: : cannot import name 'PIXELForPreTraining' from 'pixel' (unknown location)cannot import name 'PIXELForPreTraining' from 'pixel' (unknown location)

    from LatentPixel.training.pretrain_latent import train, get_config, init_wandb
    from pixel import PIXELForPreTraining, PIXELEmbeddings
ImportError: cannot import name 'PIXELForPreTraining' from 'pixel' (unknown location)
  File "/mnt/lustre/indy2lfs/work/sc118/sc118/xliao11/msc_project/LatentPixel/__init__.py", line 1, in <module>
    from .modeling import (
  File "/mnt/lustre/indy2lfs/work/sc118/sc118/xliao11/msc_project/LatentPixel/modeling/__init__.py", line 1, in <module>
    from .pixels import LPixelForMLM, LPixelForClassification
  File "/mnt/lustre/indy2lfs/work/sc118/sc118/xliao11/msc_project/LatentPixel/modeling/pixels.py", line 9, in <module>
    from pixel import PIXELForPreTraining, PIXELEmbeddings
ImportError: cannot import name 'PIXELForPreTraining' from 'pixel' (unknown location)
Traceback (most recent call last):
  File "/mnt/lustre/indy2lfs/work/sc118/sc118/xliao11/msc_project/train.py", line 1, in <module>
    from LatentPixel.training.pretrain_latent import train, get_config, init_wandb
  File "/mnt/lustre/indy2lfs/work/sc118/sc118/xliao11/msc_project/LatentPixel/__init__.py", line 1, in <module>
Traceback (most recent call last):
  File "/mnt/lustre/indy2lfs/work/sc118/sc118/xliao11/msc_project/train.py", line 1, in <module>
    from .modeling import (
  File "/mnt/lustre/indy2lfs/work/sc118/sc118/xliao11/msc_project/LatentPixel/modeling/__init__.py", line 1, in <module>
    from LatentPixel.training.pretrain_latent import train, get_config, init_wandb
  File "/mnt/lustre/indy2lfs/work/sc118/sc118/xliao11/msc_project/LatentPixel/__init__.py", line 1, in <module>
    from .pixels import LPixelForMLM, LPixelForClassification
  File "/mnt/lustre/indy2lfs/work/sc118/sc118/xliao11/msc_project/LatentPixel/modeling/pixels.py", line 9, in <module>
    from .modeling import (
  File "/mnt/lustre/indy2lfs/work/sc118/sc118/xliao11/msc_project/LatentPixel/modeling/__init__.py", line 1, in <module>
    from pixel import PIXELForPreTraining, PIXELEmbeddings
ImportError: cannot import name 'PIXELForPreTraining' from 'pixel' (unknown location)
    from .pixels import LPixelForMLM, LPixelForClassification
  File "/mnt/lustre/indy2lfs/work/sc118/sc118/xliao11/msc_project/LatentPixel/modeling/pixels.py", line 9, in <module>
    from pixel import PIXELForPreTraining, PIXELEmbeddings
ImportError: cannot import name 'PIXELForPreTraining' from 'pixel' (unknown location)
Traceback (most recent call last):
  File "/mnt/lustre/indy2lfs/work/sc118/sc118/xliao11/msc_project/train.py", line 1, in <module>
    from LatentPixel.training.pretrain_latent import train, get_config, init_wandb
  File "/mnt/lustre/indy2lfs/work/sc118/sc118/xliao11/msc_project/LatentPixel/__init__.py", line 1, in <module>
    from .modeling import (
  File "/mnt/lustre/indy2lfs/work/sc118/sc118/xliao11/msc_project/LatentPixel/modeling/__init__.py", line 1, in <module>
    from .pixels import LPixelForMLM, LPixelForClassification
  File "/mnt/lustre/indy2lfs/work/sc118/sc118/xliao11/msc_project/LatentPixel/modeling/pixels.py", line 9, in <module>
    from pixel import PIXELForPreTraining, PIXELEmbeddings
ImportError: cannot import name 'PIXELForPreTraining' from 'pixel' (unknown location)
Traceback (most recent call last):
  File "/mnt/lustre/indy2lfs/work/sc118/sc118/xliao11/msc_project/train.py", line 1, in <module>
    from LatentPixel.training.pretrain_latent import train, get_config, init_wandb
  File "/mnt/lustre/indy2lfs/work/sc118/sc118/xliao11/msc_project/LatentPixel/__init__.py", line 1, in <module>
    from .modeling import (
  File "/mnt/lustre/indy2lfs/work/sc118/sc118/xliao11/msc_project/LatentPixel/modeling/__init__.py", line 1, in <module>
    from .pixels import LPixelForMLM, LPixelForClassification
  File "/mnt/lustre/indy2lfs/work/sc118/sc118/xliao11/msc_project/LatentPixel/modeling/pixels.py", line 9, in <module>
    from pixel import PIXELForPreTraining, PIXELEmbeddings
ImportError: cannot import name 'PIXELForPreTraining' from 'pixel' (unknown location)
Traceback (most recent call last):
  File "/mnt/lustre/indy2lfs/work/sc118/sc118/xliao11/msc_project/train.py", line 1, in <module>
    from LatentPixel.training.pretrain_latent import train, get_config, init_wandb
  File "/mnt/lustre/indy2lfs/work/sc118/sc118/xliao11/msc_project/LatentPixel/__init__.py", line 1, in <module>
    from .modeling import (
  File "/mnt/lustre/indy2lfs/work/sc118/sc118/xliao11/msc_project/LatentPixel/modeling/__init__.py", line 1, in <module>
    from .pixels import LPixelForMLM, LPixelForClassification
  File "/mnt/lustre/indy2lfs/work/sc118/sc118/xliao11/msc_project/LatentPixel/modeling/pixels.py", line 9, in <module>
    from pixel import PIXELForPreTraining, PIXELEmbeddings
ImportError: cannot import name 'PIXELForPreTraining' from 'pixel' (unknown location)
Traceback (most recent call last):
  File "/mnt/lustre/indy2lfs/work/sc118/sc118/xliao11/msc_project/train.py", line 1, in <module>
    from LatentPixel.training.pretrain_latent import train, get_config, init_wandb
  File "/mnt/lustre/indy2lfs/work/sc118/sc118/xliao11/msc_project/LatentPixel/__init__.py", line 1, in <module>
    from .modeling import (
  File "/mnt/lustre/indy2lfs/work/sc118/sc118/xliao11/msc_project/LatentPixel/modeling/__init__.py", line 1, in <module>
    from .pixels import LPixelForMLM, LPixelForClassification
  File "/mnt/lustre/indy2lfs/work/sc118/sc118/xliao11/msc_project/LatentPixel/modeling/pixels.py", line 9, in <module>
    from pixel import PIXELForPreTraining, PIXELEmbeddings
ImportError: cannot import name 'PIXELForPreTraining' from 'pixel' (unknown location)
Traceback (most recent call last):
  File "/mnt/lustre/indy2lfs/work/sc118/sc118/xliao11/msc_project/train.py", line 1, in <module>
    from LatentPixel.training.pretrain_latent import train, get_config, init_wandb
  File "/mnt/lustre/indy2lfs/work/sc118/sc118/xliao11/msc_project/LatentPixel/__init__.py", line 1, in <module>
    from .modeling import (
  File "/mnt/lustre/indy2lfs/work/sc118/sc118/xliao11/msc_project/LatentPixel/modeling/__init__.py", line 1, in <module>
    from .pixels import LPixelForMLM, LPixelForClassification
  File "/mnt/lustre/indy2lfs/work/sc118/sc118/xliao11/msc_project/LatentPixel/modeling/pixels.py", line 9, in <module>
    from pixel import PIXELForPreTraining, PIXELEmbeddings
ImportError: cannot import name 'PIXELForPreTraining' from 'pixel' (unknown location)
Traceback (most recent call last):
  File "/mnt/lustre/indy2lfs/work/sc118/sc118/xliao11/msc_project/train.py", line 1, in <module>
    from LatentPixel.training.pretrain_latent import train, get_config, init_wandb
  File "/mnt/lustre/indy2lfs/work/sc118/sc118/xliao11/msc_project/LatentPixel/__init__.py", line 1, in <module>
    from .modeling import (
  File "/mnt/lustre/indy2lfs/work/sc118/sc118/xliao11/msc_project/LatentPixel/modeling/__init__.py", line 1, in <module>
    from .pixels import LPixelForMLM, LPixelForClassification
  File "/mnt/lustre/indy2lfs/work/sc118/sc118/xliao11/msc_project/LatentPixel/modeling/pixels.py", line 9, in <module>
    from pixel import PIXELForPreTraining, PIXELEmbeddings
ImportError: cannot import name 'PIXELForPreTraining' from 'pixel' (unknown location)
Traceback (most recent call last):
  File "/mnt/lustre/indy2lfs/work/sc118/sc118/xliao11/msc_project/train.py", line 1, in <module>
    from LatentPixel.training.pretrain_latent import train, get_config, init_wandb
  File "/mnt/lustre/indy2lfs/work/sc118/sc118/xliao11/msc_project/LatentPixel/__init__.py", line 1, in <module>
    from .modeling import (
  File "/mnt/lustre/indy2lfs/work/sc118/sc118/xliao11/msc_project/LatentPixel/modeling/__init__.py", line 1, in <module>
    from .pixels import LPixelForMLM, LPixelForClassification
  File "/mnt/lustre/indy2lfs/work/sc118/sc118/xliao11/msc_project/LatentPixel/modeling/pixels.py", line 9, in <module>
    from pixel import PIXELForPreTraining, PIXELEmbeddings
ImportError: cannot import name 'PIXELForPreTraining' from 'pixel' (unknown location)
ERROR:torch.distributed.elastic.multiprocessing.api:failed (exitcode: 1) local_rank: 0 (pid: 2869286) of binary: /work/sc118/sc118/xliao11/miniconda3/envs/latent/bin/python
ERROR:torch.distributed.elastic.multiprocessing.api:failed (exitcode: 1) local_rank: 0 (pid: 60264) of binary: /work/sc118/sc118/xliao11/miniconda3/envs/latent/bin/python
ERROR:torch.distributed.elastic.multiprocessing.api:failed (exitcode: 1) local_rank: 0 (pid: 2149579) of binary: /work/sc118/sc118/xliao11/miniconda3/envs/latent/bin/python
ERROR:torch.distributed.elastic.multiprocessing.api:failed (exitcode: 1) local_rank: 0 (pid: 183743) of binary: /work/sc118/sc118/xliao11/miniconda3/envs/latent/bin/python
Traceback (most recent call last):
  File "/work/sc118/sc118/xliao11/miniconda3/envs/latent/bin/torchrun", line 33, in <module>
    sys.exit(load_entry_point('torch==2.0.1', 'console_scripts', 'torchrun')())
  File "/work/sc118/sc118/xliao11/miniconda3/envs/latent/lib/python3.10/site-packages/torch/distributed/elastic/multiprocessing/errors/__init__.py", line 346, in wrapper
    return f(*args, **kwargs)
  File "/work/sc118/sc118/xliao11/miniconda3/envs/latent/lib/python3.10/site-packages/torch/distributed/run.py", line 794, in main
Traceback (most recent call last):
  File "/work/sc118/sc118/xliao11/miniconda3/envs/latent/bin/torchrun", line 33, in <module>
Traceback (most recent call last):
  File "/work/sc118/sc118/xliao11/miniconda3/envs/latent/bin/torchrun", line 33, in <module>
    sys.exit(load_entry_point('torch==2.0.1', 'console_scripts', 'torchrun')())
  File "/work/sc118/sc118/xliao11/miniconda3/envs/latent/lib/python3.10/site-packages/torch/distributed/elastic/multiprocessing/errors/__init__.py", line 346, in wrapper
Traceback (most recent call last):
  File "/work/sc118/sc118/xliao11/miniconda3/envs/latent/bin/torchrun", line 33, in <module>
    run(args)
  File "/work/sc118/sc118/xliao11/miniconda3/envs/latent/lib/python3.10/site-packages/torch/distributed/run.py", line 785, in run
    return f(*args, **kwargs)
  File "/work/sc118/sc118/xliao11/miniconda3/envs/latent/lib/python3.10/site-packages/torch/distributed/run.py", line 794, in main
    sys.exit(load_entry_point('torch==2.0.1', 'console_scripts', 'torchrun')())
  File "/work/sc118/sc118/xliao11/miniconda3/envs/latent/lib/python3.10/site-packages/torch/distributed/elastic/multiprocessing/errors/__init__.py", line 346, in wrapper
    sys.exit(load_entry_point('torch==2.0.1', 'console_scripts', 'torchrun')())
  File "/work/sc118/sc118/xliao11/miniconda3/envs/latent/lib/python3.10/site-packages/torch/distributed/elastic/multiprocessing/errors/__init__.py", line 346, in wrapper
    elastic_launch(
  File "/work/sc118/sc118/xliao11/miniconda3/envs/latent/lib/python3.10/site-packages/torch/distributed/launcher/api.py", line 134, in __call__
    return f(*args, **kwargs)
  File "/work/sc118/sc118/xliao11/miniconda3/envs/latent/lib/python3.10/site-packages/torch/distributed/run.py", line 794, in main
    return launch_agent(self._config, self._entrypoint, list(args))
    run(args)
  File "/work/sc118/sc118/xliao11/miniconda3/envs/latent/lib/python3.10/site-packages/torch/distributed/launcher/api.py", line 250, in launch_agent
  File "/work/sc118/sc118/xliao11/miniconda3/envs/latent/lib/python3.10/site-packages/torch/distributed/run.py", line 785, in run
    return f(*args, **kwargs)
  File "/work/sc118/sc118/xliao11/miniconda3/envs/latent/lib/python3.10/site-packages/torch/distributed/run.py", line 794, in main
    run(args)
  File "/work/sc118/sc118/xliao11/miniconda3/envs/latent/lib/python3.10/site-packages/torch/distributed/run.py", line 785, in run
    raise ChildFailedError(
torch.distributed.elastic.multiprocessing.errors.ChildFailedError: 
============================================================
train.py FAILED
------------------------------------------------------------
Failures:
[1]:
  time      : 2023-10-13_10:59:26
  host      : r2i6n0.ib0.icexa.epcc.ed.ac.uk
  rank      : 1 (local_rank: 1)
  exitcode  : 1 (pid: 183744)
  error_file: <N/A>
  traceback : To enable traceback see: https://pytorch.org/docs/stable/elastic/errors.html
[2]:
  time      : 2023-10-13_10:59:26
  host      : r2i6n0.ib0.icexa.epcc.ed.ac.uk
  rank      : 2 (local_rank: 2)
  exitcode  : 1 (pid: 183745)
  error_file: <N/A>
  traceback : To enable traceback see: https://pytorch.org/docs/stable/elastic/errors.html
[3]:
  time      : 2023-10-13_10:59:26
  host      : r2i6n0.ib0.icexa.epcc.ed.ac.uk
  rank      : 3 (local_rank: 3)
  exitcode  : 1 (pid: 183746)
  error_file: <N/A>
  traceback : To enable traceback see: https://pytorch.org/docs/stable/elastic/errors.html
------------------------------------------------------------
Root Cause (first observed failure):
[0]:
  time      : 2023-10-13_10:59:26
  host      : r2i6n0.ib0.icexa.epcc.ed.ac.uk
  rank      : 0 (local_rank: 0)
  exitcode  : 1 (pid: 183743)
  error_file: <N/A>
  traceback : To enable traceback see: https://pytorch.org/docs/stable/elastic/errors.html
============================================================
    elastic_launch(
  File "/work/sc118/sc118/xliao11/miniconda3/envs/latent/lib/python3.10/site-packages/torch/distributed/launcher/api.py", line 134, in __call__
    elastic_launch(
  File "/work/sc118/sc118/xliao11/miniconda3/envs/latent/lib/python3.10/site-packages/torch/distributed/launcher/api.py", line 134, in __call__
    return launch_agent(self._config, self._entrypoint, list(args))
  File "/work/sc118/sc118/xliao11/miniconda3/envs/latent/lib/python3.10/site-packages/torch/distributed/launcher/api.py", line 250, in launch_agent
    run(args)
  File "/work/sc118/sc118/xliao11/miniconda3/envs/latent/lib/python3.10/site-packages/torch/distributed/run.py", line 785, in run
    return launch_agent(self._config, self._entrypoint, list(args))
  File "/work/sc118/sc118/xliao11/miniconda3/envs/latent/lib/python3.10/site-packages/torch/distributed/launcher/api.py", line 250, in launch_agent
    elastic_launch(
    raise ChildFailedError(
  File "/work/sc118/sc118/xliao11/miniconda3/envs/latent/lib/python3.10/site-packages/torch/distributed/launcher/api.py", line 134, in __call__
torch.distributed.elastic.multiprocessing.errors.ChildFailedError: 
============================================================
train.py FAILED
------------------------------------------------------------
Failures:
[1]:
  time      : 2023-10-13_10:59:26
  host      : r2i6n2.ib0.icexa.epcc.ed.ac.uk
  rank      : 9 (local_rank: 1)
  exitcode  : 1 (pid: 2149580)
  error_file: <N/A>
  traceback : To enable traceback see: https://pytorch.org/docs/stable/elastic/errors.html
[2]:
  time      : 2023-10-13_10:59:26
  host      : r2i6n2.ib0.icexa.epcc.ed.ac.uk
  rank      : 10 (local_rank: 2)
  exitcode  : 1 (pid: 2149581)
  error_file: <N/A>
  traceback : To enable traceback see: https://pytorch.org/docs/stable/elastic/errors.html
[3]:
  time      : 2023-10-13_10:59:26
  host      : r2i6n2.ib0.icexa.epcc.ed.ac.uk
  rank      : 11 (local_rank: 3)
  exitcode  : 1 (pid: 2149582)
  error_file: <N/A>
  traceback : To enable traceback see: https://pytorch.org/docs/stable/elastic/errors.html
------------------------------------------------------------
Root Cause (first observed failure):
[0]:
  time      : 2023-10-13_10:59:26
  host      : r2i6n2.ib0.icexa.epcc.ed.ac.uk
  rank      : 8 (local_rank: 0)
  exitcode  : 1 (pid: 2149579)
  error_file: <N/A>
  traceback : To enable traceback see: https://pytorch.org/docs/stable/elastic/errors.html
============================================================
    return launch_agent(self._config, self._entrypoint, list(args))
    raise ChildFailedError(
  File "/work/sc118/sc118/xliao11/miniconda3/envs/latent/lib/python3.10/site-packages/torch/distributed/launcher/api.py", line 250, in launch_agent
torch.distributed.elastic.multiprocessing.errors.ChildFailedError: 
============================================================
train.py FAILED
------------------------------------------------------------
Failures:
[1]:
  time      : 2023-10-13_10:59:26
  host      : r2i6n3.ib0.icexa.epcc.ed.ac.uk
  rank      : 13 (local_rank: 1)
  exitcode  : 1 (pid: 2869287)
  error_file: <N/A>
  traceback : To enable traceback see: https://pytorch.org/docs/stable/elastic/errors.html
[2]:
  time      : 2023-10-13_10:59:26
  host      : r2i6n3.ib0.icexa.epcc.ed.ac.uk
  rank      : 14 (local_rank: 2)
  exitcode  : 1 (pid: 2869288)
  error_file: <N/A>
  traceback : To enable traceback see: https://pytorch.org/docs/stable/elastic/errors.html
[3]:
  time      : 2023-10-13_10:59:26
  host      : r2i6n3.ib0.icexa.epcc.ed.ac.uk
  rank      : 15 (local_rank: 3)
  exitcode  : 1 (pid: 2869289)
  error_file: <N/A>
  traceback : To enable traceback see: https://pytorch.org/docs/stable/elastic/errors.html
------------------------------------------------------------
Root Cause (first observed failure):
[0]:
  time      : 2023-10-13_10:59:26
  host      : r2i6n3.ib0.icexa.epcc.ed.ac.uk
  rank      : 12 (local_rank: 0)
  exitcode  : 1 (pid: 2869286)
  error_file: <N/A>
  traceback : To enable traceback see: https://pytorch.org/docs/stable/elastic/errors.html
============================================================
    raise ChildFailedError(
torch.distributed.elastic.multiprocessing.errors.ChildFailedError: 
============================================================
train.py FAILED
------------------------------------------------------------
Failures:
[1]:
  time      : 2023-10-13_10:59:26
  host      : r2i6n1.ib0.icexa.epcc.ed.ac.uk
  rank      : 5 (local_rank: 1)
  exitcode  : 1 (pid: 60265)
  error_file: <N/A>
  traceback : To enable traceback see: https://pytorch.org/docs/stable/elastic/errors.html
[2]:
  time      : 2023-10-13_10:59:26
  host      : r2i6n1.ib0.icexa.epcc.ed.ac.uk
  rank      : 6 (local_rank: 2)
  exitcode  : 1 (pid: 60266)
  error_file: <N/A>
  traceback : To enable traceback see: https://pytorch.org/docs/stable/elastic/errors.html
[3]:
  time      : 2023-10-13_10:59:26
  host      : r2i6n1.ib0.icexa.epcc.ed.ac.uk
  rank      : 7 (local_rank: 3)
  exitcode  : 1 (pid: 60267)
  error_file: <N/A>
  traceback : To enable traceback see: https://pytorch.org/docs/stable/elastic/errors.html
------------------------------------------------------------
Root Cause (first observed failure):
[0]:
  time      : 2023-10-13_10:59:26
  host      : r2i6n1.ib0.icexa.epcc.ed.ac.uk
  rank      : 4 (local_rank: 0)
  exitcode  : 1 (pid: 60264)
  error_file: <N/A>
  traceback : To enable traceback see: https://pytorch.org/docs/stable/elastic/errors.html
============================================================
srun: error: r2i6n3: task 3: Exited with exit code 1
srun: launch/slurm: _step_signal: Terminating StepId=4939423.1
slurmstepd: error: *** STEP 4939423.1 ON r2i6n0 CANCELLED AT 2023-10-13T10:59:26 ***
srun: error: r2i6n2: task 2: Exited with exit code 1
srun: error: r2i6n0: task 0: Terminated
srun: error: r2i6n1: task 1: Terminated
srun: Force Terminated StepId=4939423.1
